Workbook
Name lstAction: Lists!$D$2:$D$30
Name lstAssetID: Register[Asset ID]
Name lstLocation: Lists!$C$2:$C$40
Name lstOperator: Lists!$E$2:$E$20
Name lstStatus: Lists!$B$2:$B$30
Name lstType: Lists!$A$2:$A$30
Name VerifyDays: Lists!$G$2

Sheet Dashboard
B1: Device Inventory Dashboard
B2: ="As of "&TEXT(TODAY(),"dd.mm.yyyy")&" • Source: Asset Register" -> As of 24.09.2026 • Source: Asset Register
B4: Total Devices | C4: In Use | D4: In Stock | E4: Under Repair | F4: Damaged | G4: Unverified | H4: Verify Due
B5: =ROWS(Register[Asset ID]) -> 280 | C5: =COUNTIF(Register[Status],"In Use") -> 179 | D5: =COUNTIF(Register[Status],"In Stock") -> 8 | E5: =COUNTIF(Register[Status],"Under Repair") -> 2 | F5: =COUNTIF(Register[Status],"Damaged") -> 7 | G5: =COUNTIF(Register[Status],"Unverified") -> 83 | H5: =COUNTIF(Register[Flags],"*Verify due*") -> 280
B7: Status by Device Type | M7: Data Quality Checks
B8: Device Type | C8: =Lists!$B$2 -> In Use | D8: =Lists!$B$3 -> In Stock | E8: =Lists!$B$4 -> Under Repair | F8: =Lists!$B$5 -> Damaged | G8: =Lists!$B$6 -> Unverified | H8: =Lists!$B$7 -> Not in Use | I8: =Lists!$B$8 -> Disposed | J8: =Lists!$B$9 -> Lost | K8: Total | M8: Check | N8: Count
B9: =Lists!$A$2 -> Tablet 8" | C9: =COUNTIFS(Register[Asset Type],$B9,Register[Status],C$8) -> 37 | D9: =COUNTIFS(Register[Asset Type],$B9,Register[Status],D$8) -> 0 | E9: =COUNTIFS(Register[Asset Type],$B9,Register[Status],E$8) -> 2 | F9: =COUNTIFS(Register[Asset Type],$B9,Register[Status],F$8) -> 0 | G9: =COUNTIFS(Register[Asset Type],$B9,Register[Status],G$8) -> 7 | H9: =COUNTIFS(Register[Asset Type],$B9,Register[Status],H$8) -> 0 | I9: =COUNTIFS(Register[Asset Type],$B9,Register[Status],I$8) -> 0 | J9: =COUNTIFS(Register[Asset Type],$B9,Register[Status],J$8) -> 0 | K9: =COUNTIF(Register[Asset Type],$B9) -> 46 | M9: Missing serial / IMEI | N9: =COUNTIF(Register[Flags],"*No serial*") -> 55
B10: =Lists!$A$3 -> Tablet 10" | C10: =COUNTIFS(Register[Asset Type],$B10,Register[Status],C$8) -> 20 | D10: =COUNTIFS(Register[Asset Type],$B10,Register[Status],D$8) -> 0 | E10: =COUNTIFS(Register[Asset Type],$B10,Register[Status],E$8) -> 0 | F10: =COUNTIFS(Register[Asset Type],$B10,Register[Status],F$8) -> 0 | G10: =COUNTIFS(Register[Asset Type],$B10,Register[Status],G$8) -> 0 | H10: =COUNTIFS(Register[Asset Type],$B10,Register[Status],H$8) -> 0 | I10: =COUNTIFS(Register[Asset Type],$B10,Register[Status],I$8) -> 0 | J10: =COUNTIFS(Register[Asset Type],$B10,Register[Status],J$8) -> 0 | K10: =COUNTIF(Register[Asset Type],$B10) -> 20 | M10: Duplicate serial / IMEI | N10: =COUNTIF(Register[Flags],"*Duplicate serial*") -> 4
B11: =Lists!$A$4 -> PC | C11: =COUNTIFS(Register[Asset Type],$B11,Register[Status],C$8) -> 46 | D11: =COUNTIFS(Register[Asset Type],$B11,Register[Status],D$8) -> 0 | E11: =COUNTIFS(Register[Asset Type],$B11,Register[Status],E$8) -> 0 | F11: =COUNTIFS(Register[Asset Type],$B11,Register[Status],F$8) -> 0 | G11: =COUNTIFS(Register[Asset Type],$B11,Register[Status],G$8) -> 2 | H11: =COUNTIFS(Register[Asset Type],$B11,Register[Status],H$8) -> 1 | I11: =COUNTIFS(Register[Asset Type],$B11,Register[Status],I$8) -> 0 | J11: =COUNTIFS(Register[Asset Type],$B11,Register[Status],J$8) -> 0 | K11: =COUNTIF(Register[Asset Type],$B11) -> 49 | M11: Duplicate device name | N11: =COUNTIF(Register[Flags],"*Duplicate name*") -> 2
B12: =Lists!$A$5 -> VHF | C12: =COUNTIFS(Register[Asset Type],$B12,Register[Status],C$8) -> 76 | D12: =COUNTIFS(Register[Asset Type],$B12,Register[Status],D$8) -> 8 | E12: =COUNTIFS(Register[Asset Type],$B12,Register[Status],E$8) -> 0 | F12: =COUNTIFS(Register[Asset Type],$B12,Register[Status],F$8) -> 7 | G12: =COUNTIFS(Register[Asset Type],$B12,Register[Status],G$8) -> 74 | H12: =COUNTIFS(Register[Asset Type],$B12,Register[Status],H$8) -> 0 | I12: =COUNTIFS(Register[Asset Type],$B12,Register[Status],I$8) -> 0 | J12: =COUNTIFS(Register[Asset Type],$B12,Register[Status],J$8) -> 0 | K12: =COUNTIF(Register[Asset Type],$B12) -> 165 | M12: Missing location | N12: =COUNTIF(Register[Flags],"*No location*") -> 118
B13: Total | C13: =SUM(C9:C12) -> 179 | D13: =SUM(D9:D12) -> 8 | E13: =SUM(E9:E12) -> 2 | F13: =SUM(F9:F12) -> 7 | G13: =SUM(G9:G12) -> 83 | H13: =SUM(H9:H12) -> 1 | I13: =SUM(I9:I12) -> 0 | J13: =SUM(J9:J12) -> 0 | K13: =SUM(K9:K12) -> 280 | M13: Verification due | N13: =COUNTIF(Register[Flags],"*Verify due*") -> 280
M14: Filter the Flags column on the Asset Register to see the rows.
B16: Devices by Location | M16: Quick Asset Lookup
B17: Location | C17: =Lists!$A$2 -> Tablet 8" | D17: =Lists!$A$3 -> Tablet 10" | E17: =Lists!$A$4 -> PC | F17: =Lists!$A$5 -> VHF | G17: Total | M17: Enter Asset ID → | N17: TAB8-001
B18: =Lists!$C$2 -> COD | C18: =COUNTIFS(Register[Location],$B18,Register[Asset Type],C$17) -> 21 | D18: =COUNTIFS(Register[Location],$B18,Register[Asset Type],D$17) -> 11 | E18: =COUNTIFS(Register[Location],$B18,Register[Asset Type],E$17) -> 0 | F18: =COUNTIFS(Register[Location],$B18,Register[Asset Type],F$17) -> 6 | G18: =SUM(C18:F18) -> 38 | M18: Asset Type | N18: =IFERROR(_xlfn.XLOOKUP($N$17,Register[Asset ID],Register[Asset Type])&"","Not found") -> Tablet 8"
B19: =Lists!$C$3 -> Container Yard | C19: =COUNTIFS(Register[Location],$B19,Register[Asset Type],C$17) -> 3 | D19: =COUNTIFS(Register[Location],$B19,Register[Asset Type],D$17) -> 4 | E19: =COUNTIFS(Register[Location],$B19,Register[Asset Type],E$17) -> 0 | F19: =COUNTIFS(Register[Location],$B19,Register[Asset Type],F$17) -> 3 | G19: =SUM(C19:F19) -> 10 | M19: Device Name / Code | N19: =IFERROR(_xlfn.XLOOKUP($N$17,Register[Asset ID],Register[Device Name / Code])&"","Not found") -> Tab 1
B20: =Lists!$C$4 -> Thilafushi | C20: =COUNTIFS(Register[Location],$B20,Register[Asset Type],C$17) -> 1 | D20: =COUNTIFS(Register[Location],$B20,Register[Asset Type],D$17) -> 1 | E20: =COUNTIFS(Register[Location],$B20,Register[Asset Type],E$17) -> 0 | F20: =COUNTIFS(Register[Location],$B20,Register[Asset Type],F$17) -> 0 | G20: =SUM(C20:F20) -> 2 | M20: Brand | N20: =IFERROR(_xlfn.XLOOKUP($N$17,Register[Asset ID],Register[Brand])&"","Not found")
B21: =Lists!$C$5 -> HMT | C21: =COUNTIFS(Register[Location],$B21,Register[Asset Type],C$17) -> 6 | D21: =COUNTIFS(Register[Location],$B21,Register[Asset Type],D$17) -> 4 | E21: =COUNTIFS(Register[Location],$B21,Register[Asset Type],E$17) -> 0 | F21: =COUNTIFS(Register[Location],$B21,Register[Asset Type],F$17) -> 0 | G21: =SUM(C21:F21) -> 10 | M21: Model | N21: =IFERROR(_xlfn.XLOOKUP($N$17,Register[Asset ID],Register[Model])&"","Not found")
B22: =Lists!$C$6 -> Marine Craft | C22: =COUNTIFS(Register[Location],$B22,Register[Asset Type],C$17) -> 5 | D22: =COUNTIFS(Register[Location],$B22,Register[Asset Type],D$17) -> 0 | E22: =COUNTIFS(Register[Location],$B22,Register[Asset Type],E$17) -> 0 | F22: =COUNTIFS(Register[Location],$B22,Register[Asset Type],F$17) -> 0 | G22: =SUM(C22:F22) -> 5 | M22: Serial / IMEI | N22: =IFERROR(_xlfn.XLOOKUP($N$17,Register[Asset ID],Register[Serial / IMEI])&"","Not found") -> 350675291199268
B23: =Lists!$C$7 -> Yard Office | C23: =COUNTIFS(Register[Location],$B23,Register[Asset Type],C$17) -> 1 | D23: =COUNTIFS(Register[Location],$B23,Register[Asset Type],D$17) -> 0 | E23: =COUNTIFS(Register[Location],$B23,Register[Asset Type],E$17) -> 0 | F23: =COUNTIFS(Register[Location],$B23,Register[Asset Type],F$17) -> 0 | G23: =SUM(C23:F23) -> 1 | M23: Inventory No. | N23: =IFERROR(_xlfn.XLOOKUP($N$17,Register[Asset ID],Register[Inventory No.])&"","Not found")
B24: =Lists!$C$8 -> IT | C24: =COUNTIFS(Register[Location],$B24,Register[Asset Type],C$17) -> 2 | D24: =COUNTIFS(Register[Location],$B24,Register[Asset Type],D$17) -> 0 | E24: =COUNTIFS(Register[Location],$B24,Register[Asset Type],E$17) -> 0 | F24: =COUNTIFS(Register[Location],$B24,Register[Asset Type],F$17) -> 0 | G24: =SUM(C24:F24) -> 2 | M24: Asset No. | N24: =IFERROR(_xlfn.XLOOKUP($N$17,Register[Asset ID],Register[Asset No.])&"","Not found") -> MPL-CGO-OEQ-TBLT-00039
B25: =Lists!$C$9 -> POD-MCH | C25: =COUNTIFS(Register[Location],$B25,Register[Asset Type],C$17) -> 0 | D25: =COUNTIFS(Register[Location],$B25,Register[Asset Type],D$17) -> 0 | E25: =COUNTIFS(Register[Location],$B25,Register[Asset Type],E$17) -> 0 | F25: =COUNTIFS(Register[Location],$B25,Register[Asset Type],F$17) -> 67 | G25: =SUM(C25:F25) -> 67 | M25: SIM / Operator | N25: =IFERROR(_xlfn.XLOOKUP($N$17,Register[Asset ID],Register[SIM / Operator])&"","Not found") -> Dhiraagu 10GB
B26: =Lists!$C$10 -> POD-HMT | C26: =COUNTIFS(Register[Location],$B26,Register[Asset Type],C$17) -> 0 | D26: =COUNTIFS(Register[Location],$B26,Register[Asset Type],D$17) -> 0 | E26: =COUNTIFS(Register[Location],$B26,Register[Asset Type],E$17) -> 0 | F26: =COUNTIFS(Register[Location],$B26,Register[Asset Type],F$17) -> 10 | G26: =SUM(C26:F26) -> 10 | M26: Location | N26: =IFERROR(_xlfn.XLOOKUP($N$17,Register[Asset ID],Register[Location])&"","Not found") -> COD
B27: =Lists!$C$11 -> POD Office | C27: =COUNTIFS(Register[Location],$B27,Register[Asset Type],C$17) -> 0 | D27: =COUNTIFS(Register[Location],$B27,Register[Asset Type],D$17) -> 0 | E27: =COUNTIFS(Register[Location],$B27,Register[Asset Type],E$17) -> 0 | F27: =COUNTIFS(Register[Location],$B27,Register[Asset Type],F$17) -> 5 | G27: =SUM(C27:F27) -> 5 | M27: Assigned To / Shift | N27: =IFERROR(_xlfn.XLOOKUP($N$17,Register[Asset ID],Register[Assigned To / Shift])&"","Not found") -> B Tallies
B28: =Lists!$C$12 -> Gear Store | C28: =COUNTIFS(Register[Location],$B28,Register[Asset Type],C$17) -> 0 | D28: =COUNTIFS(Register[Location],$B28,Register[Asset Type],D$17) -> 0 | E28: =COUNTIFS(Register[Location],$B28,Register[Asset Type],E$17) -> 0 | F28: =COUNTIFS(Register[Location],$B28,Register[Asset Type],F$17) -> 1 | G28: =SUM(C28:F28) -> 1 | M28: Status | N28: =IFERROR(_xlfn.XLOOKUP($N$17,Register[Asset ID],Register[Status])&"","Not found") -> In Use
B29: =Lists!$C$13 -> Cargo Office | C29: =COUNTIFS(Register[Location],$B29,Register[Asset Type],C$17) -> 0 | D29: =COUNTIFS(Register[Location],$B29,Register[Asset Type],D$17) -> 0 | E29: =COUNTIFS(Register[Location],$B29,Register[Asset Type],E$17) -> 0 | F29: =COUNTIFS(Register[Location],$B29,Register[Asset Type],F$17) -> 1 | G29: =SUM(C29:F29) -> 1 | M29: Issued Date | N29: =IFERROR(TEXT(_xlfn.XLOOKUP($N$17,Register[Asset ID],Register[Issued Date]),"dd.mm.yyyy;;"),"")
B30: =Lists!$C$14 -> MCD | C30: =COUNTIFS(Register[Location],$B30,Register[Asset Type],C$17) -> 0 | D30: =COUNTIFS(Register[Location],$B30,Register[Asset Type],D$17) -> 0 | E30: =COUNTIFS(Register[Location],$B30,Register[Asset Type],E$17) -> 0 | F30: =COUNTIFS(Register[Location],$B30,Register[Asset Type],F$17) -> 3 | G30: =SUM(C30:F30) -> 3 | M30: Last Verified | N30: =IFERROR(TEXT(_xlfn.XLOOKUP($N$17,Register[Asset ID],Register[Last Verified]),"dd.mm.yyyy;;"),"")
B31: =Lists!$C$15 -> Office | C31: =COUNTIFS(Register[Location],$B31,Register[Asset Type],C$17) -> 0 | D31: =COUNTIFS(Register[Location],$B31,Register[Asset Type],D$17) -> 0 | E31: =COUNTIFS(Register[Location],$B31,Register[Asset Type],E$17) -> 0 | F31: =COUNTIFS(Register[Location],$B31,Register[Asset Type],F$17) -> 2 | G31: =SUM(C31:F31) -> 2 | M31: Flags | N31: =IFERROR(_xlfn.XLOOKUP($N$17,Register[Asset ID],Register[Flags])&"","Not found") -> Verify due
B32: =Lists!$C$16 -> MCH | C32: =COUNTIFS(Register[Location],$B32,Register[Asset Type],C$17) -> 0 | D32: =COUNTIFS(Register[Location],$B32,Register[Asset Type],D$17) -> 0 | E32: =COUNTIFS(Register[Location],$B32,Register[Asset Type],E$17) -> 0 | F32: =COUNTIFS(Register[Location],$B32,Register[Asset Type],F$17) -> 5 | G32: =SUM(C32:F32) -> 5 | M32: Remarks | N32: =IFERROR(_xlfn.XLOOKUP($N$17,Register[Asset ID],Register[Remarks])&"","Not found") -> At COD / Currently in use
B33: (No location) | C33: =COUNTIFS(Register[Location],"",Register[Asset Type],C$17) -> 7 | D33: =COUNTIFS(Register[Location],"",Register[Asset Type],D$17) -> 0 | E33: =COUNTIFS(Register[Location],"",Register[Asset Type],E$17) -> 49 | F33: =COUNTIFS(Register[Location],"",Register[Asset Type],F$17) -> 62 | G33: =SUM(C33:F33) -> 118 | M33: Last movement | N33: =IFERROR(TEXT(_xlfn.MAXIFS(MoveLog[Date],MoveLog[Asset ID],$N$17),"dd.mm.yyyy;;")&"","")
B34: Total | C34: =SUM(C18:C33) -> 46 | D34: =SUM(D18:D33) -> 20 | E34: =SUM(E18:E33) -> 49 | F34: =SUM(F18:F33) -> 165 | G34: =SUM(G18:G33) -> 280

Sheet Asset Register
A1: Asset Register — Tablets, PCs & VHFs
A2: Master list (one row per device). Edit here. Use the Movement Log to record hand-overs & repairs. Columns Q–R are calculated.
A4: Asset ID | B4: Asset Type | C4: Device Name / Code | D4: Brand | E4: Model | F4: Serial / IMEI | G4: Inventory No. | H4: Asset No. | I4: Alt Ref No. | J4: SIM / Operator | K4: Location | L4: Assigned To / Shift | M4: Status | N4: Issued Date | O4: Last OS Update | P4: Last Verified | Q4: Days Since Verified | R4: Flags | S4: Repair History | T4: Remarks | U4: Source
A5: TAB8-001 | B5: Tablet 8" | C5: Tab 1 | F5: 350675291199268 | H5: MPL-CGO-OEQ-TBLT-00039 | I5: MPL14916 | J5: Dhiraagu 10GB | K5: COD | L5: B Tallies | M5: In Use | Q5: =IF(Register[[#This Row],[Last Verified]]="","",TODAY()-Register[[#This Row],[Last Verified]]) | R5: =_xlfn.TEXTJOIN(", ",TRUE,IF(Register[[#This Row],[Serial / IMEI]]="","No serial",""),IF(AND(Register[[#This Row],[Serial / IMEI]]<>"",COUNTIF(Register[Serial / IMEI],Register[[#This Row],[Serial / IMEI]])>1),"Duplicate serial",""),IF(AND(Register[[#This Row],[Asset Type]]<>"VHF",COUNTIFS(Register[Device Name / Code],Register[[#This Row],[Device Name / Code]],Register[Asset Type],Register[[#This Row],[Asset Type]])>1),"Duplicate name",""),IF(Register[[#This Row],[Location]]="","No location",""),IF(OR(Register[[#This Row],[Last Verified]]="",N(Register[[#This Row],[Days Since Verified]])>VerifyDays),"Verify due","")) -> Verify due | T5: At COD / Currently in use | U5: Tab 8" row 3
A6: TAB8-002 | B6: Tablet 8" | C6: Tab 2 | F6: 350675291330186 | H6: MPL-CGO-OEQ-TBLT-00040 | I6: MPL14915 | J6: Dhiraagu 10GB | K6: Container Yard | L6: C Yard | M6: In Use | N6: 44829 | Q6: =IF(Register[[#This Row],[Last Verified]]="","",TODAY()-Register[[#This Row],[Last Verified]]) | R6: =_xlfn.TEXTJOIN(", ",TRUE,IF(Register[[#This Row],[Serial / IMEI]]="","No serial",""),IF(AND(Register[[#This Row],[Serial / IMEI]]<>"",COUNTIF(Register[Serial / IMEI],Register[[#This Row],[Serial / IMEI]])>1),"Duplicate serial",""),IF(AND(Register[[#This Row],[Asset Type]]<>"VHF",COUNTIFS(Register[Device Name / Code],Register[[#This Row],[Device Name / Code]],Register[Asset Type],Register[[#This Row],[Asset Type]])>1),"Duplicate name",""),IF(Register[[#This Row],[Location]]="","No location",""),IF(OR(Register[[#This Row],[Last Verified]]="",N(Register[[#This Row],[Days Since Verified]])>VerifyDays),"Verify due","")) -> Verify due | T6: Container Yard (25.09.2022) | U6: Tab 8" row 4
A7: TAB8-003 | B7: Tablet 8" | C7: Tab 3 | F7: 350675291332695 | H7: MPL-CGO-OEQ-TBLT-00041 | I7: MPL14914 | J7: Dhiraagu 10GB | K7: COD | L7: C Tallies | M7: In Use | O7: 44592 | Q7: =IF(Register[[#This Row],[Last Verified]]="","",TODAY()-Register[[#This Row],[Last Verified]]) | R7: =_xlfn.TEXTJOIN(", ",TRUE,IF(Register[[#This Row],[Serial / IMEI]]="","No serial",""),IF(AND(Register[[#This Row],[Serial / IMEI]]<>"",COUNTIF(Register[Serial / IMEI],Register[[#This Row],[Serial / IMEI]])>1),"Duplicate serial",""),IF(AND(Register[[#This Row],[Asset Type]]<>"VHF",COUNTIFS(Register[Device Name / Code],Register[[#This Row],[Device Name / Code]],Register[Asset Type],Register[[#This Row],[Asset Type]])>1),"Duplicate name",""),IF(Register[[#This Row],[Location]]="","No location",""),IF(OR(Register[[#This Row],[Last Verified]]="",N(Register[[#This Row],[Days Since Verified]])>VerifyDays),"Verify due","")) -> Verify due | S7: Battery Replaced 11.12.2024 | T7: At COD / Currently in use | U7: Tab 8" row 5
A8: TAB8-004 | B8: Tablet 8" | C8: Tab 4 | F8: 350675291222482 | H8: MPL-CGO-OEQ-TBLT-00042 | I8: MPL14913 | J8: Dhiraagu 10GB | K8: Container Yard | L8: C Yard | M8: In Use | N8: 44348 | Q8: =IF(Register[[#This Row],[Last Verified]]="","",TODAY()-Register[[#This Row],[Last Verified]]) | R8: =_xlfn.TEXTJOIN(", ",TRUE,IF(Register[[#This Row],[Serial / IMEI]]="","No serial",""),IF(AND(Register[[#This Row],[Serial / IMEI]]<>"",COUNTIF(Register[Serial / IMEI],Register[[#This Row],[Serial / IMEI]])>1),"Duplicate serial",""),IF(AND(Register[[#This Row],[Asset Type]]<>"VHF",COUNTIFS(Register[Device Name / Code],Register[[#This Row],[Device Name / Code]],Register[Asset Type],Register[[#This Row],[Asset Type]])>1),"Duplicate name",""),IF(Register[[#This Row],[Location]]="","No location",""),IF(OR(Register[[#This Row],[Last Verified]]="",N(Register[[#This Row],[Days Since Verified]])>VerifyDays),"Verify due","")) -> Verify due | T8: Container Yard (01.06.2021) | U8: Tab 8" row 6
A9: TAB8-005 | B9: Tablet 8" | C9: Tab 5 | F9: 350675291334022 | H9: MPL-CGO-OEQ-TBLT-00043 | I9: MPL14912 | J9: Dhiraagu 10GB | K9: Thilafushi | L9: Security | M9: In Use | Q9: =IF(Register[[#This Row],[Last Verified]]="","",TODAY()-Register[[#This Row],[Last Verified]]) | R9: =_xlfn.TEXTJOIN(", ",TRUE,IF(Register[[#This Row],[Serial / IMEI]]="","No serial",""),IF(AND(Register[[#This Row],[Serial / IMEI]]<>"",COUNTIF(Register[Serial / IMEI],Register[[#This Row],[Serial / IMEI]])>1),"Duplicate serial",""),IF(AND(Register[[#This Row],[Asset Type]]<>"VHF",COUNTIFS(Register[Device Name / Code],Register[[#This Row],[Device Name / Code]],Register[Asset Type],Register[[#This Row],[Asset Type]])>1),"Duplicate name",""),IF(Register[[#This Row],[Location]]="","No location",""),IF(OR(Register[[#This Row],[Last Verified]]="",N(Register[[#This Row],[Days Since Verified]])>VerifyDays),"Verify due","")) -> Verify due | T9: Security for Thilafushi Ops | U9: Tab 8" row 7
A10: TAB8-006 | B10: Tablet 8" | C10: Tab 6 | F10: 350675291228877 | H10: MPL-CGO-OEQ-TBLT-00044 | I10: MPL14911 | J10: Dhiraagu 10GB | K10: HMT | M10: In Use | N10: 44339 | Q10: =IF(Register[[#This Row],[Last Verified]]="","",TODAY()-Register[[#This Row],[Last Verified]]) | R10: =_xlfn.TEXTJOIN(", ",TRUE,IF(Register[[#This Row],[Serial / IMEI]]="","No serial",""),IF(AND(Register[[#This Row],[Serial / IMEI]]<>"",COUNTIF(Register[Serial / IMEI],Register[[#This Row],[Serial / IMEI]])>1),"Duplicate serial",""),IF(AND(Register[[#This Row],[Asset Type]]<>"VHF",COUNTIFS(Register[Device Name / Code],Register[[#This Row],[Device Name / Code]],Register[Asset Type],Register[[#This Row],[Asset Type]])>1),"Duplicate name",""),IF(Register[[#This Row],[Location]]="","No location",""),IF(OR(Register[[#This Row],[Last Verified]]="",N(Register[[#This Row],[Days Since Verified]])>VerifyDays),"Verify due","")) -> Verify due | T10: Use in HMT(sent on 23.05.2021) | U10: Tab 8" row 8
A11: TAB8-007 | B11: Tablet 8" | C11: Tab 7 | F11: 350675291228992 | H11: MPL-CGO-OEQ-TBLT-00045 | I11: MPL14910 | J11: Dhiraagu 10GB | K11: HMT | M11: In Use | N11: 44339 | Q11: =IF(Register[[#This Row],[Last Verified]]="","",TODAY()-Register[[#This Row],[Last Verified]]) | R11: =_xlfn.TEXTJOIN(", ",TRUE,IF(Register[[#This Row],[Serial / IMEI]]="","No serial",""),IF(AND(Register[[#This Row],[Serial / IMEI]]<>"",COUNTIF(Register[Serial / IMEI],Register[[#This Row],[Serial / IMEI]])>1),"Duplicate serial",""),IF(AND(Register[[#This Row],[Asset Type]]<>"VHF",COUNTIFS(Register[Device Name / Code],Register[[#This Row],[Device Name / Code]],Register[Asset Type],Register[[#This Row],[Asset Type]])>1),"Duplicate name",""),IF(Register[[#This Row],[Location]]="","No location",""),IF(OR(Register[[#This Row],[Last Verified]]="",N(Register[[#This Row],[Days Since Verified]])>VerifyDays),"Verify due","")) -> Verify due | T11: Use in HMT(sent on 23.05.2021) | U11: Tab 8" row 9
A12: TAB8-008 | B12: Tablet 8" | C12: Tab 8 | F12: 350675291331135 | H12: MPL-CGO-OEQ-TBLT-00046 | I12: MPL14909 | J12: Dhiraagu 10GB | K12: COD | L12: A Tallies | M12: In Use | Q12: =IF(Register[[#This Row],[Last Verified]]="","",TODAY()-Register[[#This Row],[Last Verified]]) | R12: =_xlfn.TEXTJOIN(", ",TRUE,IF(Register[[#This Row],[Serial / IMEI]]="","No serial",""),IF(AND(Register[[#This Row],[Serial / IMEI]]<>"",COUNTIF(Register[Serial / IMEI],Register[[#This Row],[Serial / IMEI]])>1),"Duplicate serial",""),IF(AND(Register[[#This Row],[Asset Type]]<>"VHF",COUNTIFS(Register[Device Name / Code],Register[[#This Row],[Device Name / Code]],Register[Asset Type],Register[[#This Row],[Asset Type]])>1),"Duplicate name",""),IF(Register[[#This Row],[Location]]="","No location",""),IF(OR(Register[[#This Row],[Last Verified]]="",N(Register[[#This Row],[Days Since Verified]])>VerifyDays),"Verify due","")) -> Verify due | T12: At COD / Currently in use | U12: Tab 8" row 10
A13: TAB8-009 | B13: Tablet 8" | C13: Tab 9 | F13: 350675291329451 | H13: MPL-CGO-OEQ-TBLT-00047 | I13: MPL14908 | J13: Dhiraagu 10GB | K13: COD | L13: A Tallies | M13: In Use | Q13: =IF(Register[[#This Row],[Last Verified]]="","",TODAY()-Register[[#This Row],[Last Verified]]) | R13: =_xlfn.TEXTJOIN(", ",TRUE,IF(Register[[#This Row],[Serial / IMEI]]="","No serial",""),IF(AND(Register[[#This Row],[Serial / IMEI]]<>"",COUNTIF(Register[Serial / IMEI],Register[[#This Row],[Serial / IMEI]])>1),"Duplicate serial",""),IF(AND(Register[[#This Row],[Asset Type]]<>"VHF",COUNTIFS(Register[Device Name / Code],Register[[#This Row],[Device Name / Code]],Register[Asset Type],Register[[#This Row],[Asset Type]])>1),"Duplicate name",""),IF(Register[[#This Row],[Location]]="","No location",""),IF(OR(Register[[#This Row],[Last Verified]]="",N(Register[[#This Row],[Days Since Verified]])>VerifyDays),"Verify due","")) -> Verify due | T13: At COD / Currently in use | U13: Tab 8" row 11
A14: TAB8-010 | B14: Tablet 8" | C14: Tab 10 | F14: 350675291331085 | H14: MPL-CGO-OEQ-TBLT-00048 | I14: MPL14907 | J14: Dhiraagu 10GB | K14: Yard Office | M14: In Use | N14: 44307 | Q14: =IF(Register[[#This Row],[Last Verified]]="","",TODAY()-Register[[#This Row],[Last Verified]]) | R14: =_xlfn.TEXTJOIN(", ",TRUE,IF(Register[[#This Row],[Serial / IMEI]]="","No serial",""),IF(AND(Register[[#This Row],[Serial / IMEI]]<>"",COUNTIF(Register[Serial / IMEI],Register[[#This Row],[Serial / IMEI]])>1),"Duplicate serial",""),IF(AND(Register[[#This Row],[Asset Type]]<>"VHF",COUNTIFS(Register[Device Name / Code],Register[[#This Row],[Device Name / Code]],Register[Asset Type],Register[[#This Row],[Asset Type]])>1),"Duplicate name",""),IF(Register[[#This Row],[Location]]="","No location",""),IF(OR(Register[[#This Row],[Last Verified]]="",N(Register[[#This Row],[Days Since Verified]])>VerifyDays),"Verify due","")) -> Verify due | T14: Yard Office (21.04.2021) | U14: Tab 8" row 12
A15: TAB8-011 | B15: Tablet 8" | C15: Tab 11 | F15: 350675291228844 | H15: MPL-CGO-OEQ-TBLT-00051 | I15: MPL14906 | J15: Dhiraagu 10GB | K15: COD | L15: B Tallies | M15: In Use | Q15: =IF(Register[[#This Row],[Last Verified]]="","",TODAY()-Register[[#This Row],[Last Verified]]) | R15: =_xlfn.TEXTJOIN(", ",TRUE,IF(Register[[#This Row],[Serial / IMEI]]="","No serial",""),IF(AND(Register[[#This Row],[Serial / IMEI]]<>"",COUNTIF(Register[Serial / IMEI],Register[[#This Row],[Serial / IMEI]])>1),"Duplicate serial",""),IF(AND(Register[[#This Row],[Asset Type]]<>"VHF",COUNTIFS(Register[Device Name / Code],Register[[#This Row],[Device Name / Code]],Register[Asset Type],Register[[#This Row],[Asset Type]])>1),"Duplicate name",""),IF(Register[[#This Row],[Location]]="","No location",""),IF(OR(Register[[#This Row],[Last Verified]]="",N(Register[[#This Row],[Days Since Verified]])>VerifyDays),"Verify due","")) -> Verify due | T15: At COD / Currently in use | U15: Tab 8" row 13
A16: TAB8-012 | B16: Tablet 8" | C16: Tab 12 | F16: 350675291332265 | H16: MPL-CGO-OEQ-TBLT-00052 | I16: MPL14905 | J16: Dhiraagu 10GB | K16: IT | M16: Under Repair | Q16: =IF(Register[[#This Row],[Last Verified]]="","",TODAY()-Register[[#This Row],[Last Verified]]) | R16: =_xlfn.TEXTJOIN(", ",TRUE,IF(Register[[#This Row],[Serial / IMEI]]="","No serial",""),IF(AND(Register[[#This Row],[Serial / IMEI]]<>"",COUNTIF(Register[Serial / IMEI],Register[[#This Row],[Serial / IMEI]])>1),"Duplicate serial",""),IF(AND(Register[[#This Row],[Asset Type]]<>"VHF",COUNTIFS(Register[Device Name / Code],Register[[#This Row],[Device Name / Code]],Register[Asset Type],Register[[#This Row],[Asset Type]])>1),"Duplicate name",""),IF(Register[[#This Row],[Location]]="","No location",""),IF(OR(Register[[#This Row],[Last Verified]]="",N(Register[[#This Row],[Days Since Verified]])>VerifyDays),"Verify due","")) -> Verify due | T16: At IT (Tab back light issue) - Given to IT for Repair | U16: Tab 8" row 14
A17: TAB8-013 | B17: Tablet 8" | C17: Tab 13 | F17: 350675291222417 | H17: MPL-CGO-OEQ-TBLT-00053 | I17: MPL14904 | J17: Dhiraagu 10GB | K17: HMT | L17: HMT | M17: In Use | N17: 45729 | O17: 44592 | Q17: =IF(Register[[#This Row],[Last Verified]]="","",TODAY()-Register[[#This Row],[Last Verified]]) | R17: =_xlfn.TEXTJOIN(", ",TRUE,IF(Register[[#This Row],[Serial / IMEI]]="","No serial",""),IF(AND(Register[[#This Row],[Serial / IMEI]]<>"",COUNTIF(Register[Serial / IMEI],Register[[#This Row],[Serial / IMEI]])>1),"Duplicate serial",""),IF(AND(Register[[#This Row],[Asset Type]]<>"VHF",COUNTIFS(Register[Device Name / Code],Register[[#This Row],[Device Name / Code]],Register[Asset Type],Register[[#This Row],[Asset Type]])>1),"Duplicate name",""),IF(Register[[#This Row],[Location]]="","No location",""),IF(OR(Register[[#This Row],[Last Verified]]="",N(Register[[#This Row],[Days Since Verified]])>VerifyDays),"Verify due","")) -> Verify due | T17: At COD / Currently in use, HMT 13.03.2025 | U17: Tab 8" row 15
A18: TAB8-014 | B18: Tablet 8" | C18: Tab 14 | F18: 350675291222318 | H18: MPL-CGO-OEQ-TBLT-00050 | I18: MPL14903 | J18: Dhiraagu 10GB | K18: IT | M18: Under Repair | Q18: =IF(Register[[#This Row],[Last Verified]]="","",TODAY()-Register[[#This Row],[Last Verified]]) | R18: =_xlfn.TEXTJOIN(", ",TRUE,IF(Register[[#This Row],[Serial / IMEI]]="","No serial",""),IF(AND(Register[[#This Row],[Serial / IMEI]]<>"",COUNTIF(Register[Serial / IMEI],Register[[#This Row],[Serial / IMEI]])>1),"Duplicate serial",""),IF(AND(Register[[#This Row],[Asset Type]]<>"VHF",COUNTIFS(Register[Device Name / Code],Register[[#This Row],[Device Name / Code]],Register[Asset Type],Register[[#This Row],[Asset Type]])>1),"Duplicate name",""),IF(Register[[#This Row],[Location]]="","No location",""),IF(OR(Register[[#This Row],[Last Verified]]="",N(Register[[#This Row],[Days Since Verified]])>VerifyDays),"Verify due","")) -> Verify due | T18: At IT (Tab back light issue) - Given to IT for Repair | U18: Tab 8" row 16
A19: TAB8-015 | B19: Tablet 8" | C19: Tab 15 | F19: 350675291222557 | H19: MPL-CGO-OEQ-TBLT-00049 | I19: MPL14902 | J19: Dhiraagu 10GB | K19: COD | L19: B Tallies | M19: In Use | Q19: =IF(Register[[#This Row],[Last Verified]]="","",TODAY()-Register[[#This Row],[Last Verified]]) | R19: =_xlfn.TEXTJOIN(", ",TRUE,IF(Register[[#This Row],[Serial / IMEI]]="","No serial",""),IF(AND(Register[[#This Row],[Serial / IMEI]]<>"",COUNTIF(Register[Serial / IMEI],Register[[#This Row],[Serial / IMEI]])>1),"Duplicate serial",""),IF(AND(Register[[#This Row],[Asset Type]]<>"VHF",COUNTIFS(Register[Device Name / Code],Register[[#This Row],[Device Name / Code]],Register[Asset Type],Register[[#This Row],[Asset Type]])>1),"Duplicate name",""),IF(Register[[#This Row],[Location]]="","No location",""),IF(OR(Register[[#This Row],[Last Verified]]="",N(Register[[#This Row],[Days Since Verified]])>VerifyDays),"Verify due","")) -> Verify due | T19: At COD / Currently in use | U19: Tab 8" row 17
A20: TAB8-016 | B20: Tablet 8" | C20: Tab 16 | F20: 350675292375321 | G20: MPL12613 | H20: MPL-CGO-OEQ-TBLT-00064 | I20: MPL12607 | J20: Dhiraagu 10GB | M20: Unverified | Q20: =IF(Register[[#This Row],[Last Verified]]="","",TODAY()-Register[[#This Row],[Last Verified]]) | R20: =_xlfn.TEXTJOIN(", ",TRUE,IF(Register[[#This Row],[Serial / IMEI]]="","No serial",""),IF(AND(Register[[#This Row],[Serial / IMEI]]<>"",COUNTIF(Register[Serial / IMEI],Register[[#This Row],[Serial / IMEI]])>1),"Duplicate serial",""),IF(AND(Register[[#This Row],[Asset Type]]<>"VHF",COUNTIFS(Register[Device Name / Code],Register[[#This Row],[Device Name / Code]],Register[Asset Type],Register[[#This Row],[Asset Type]])>1),"Duplicate name",""),IF(Register[[#This Row],[Location]]="","No location",""),IF(OR(Register[[#This Row],[Last Verified]]="",N(Register[[#This Row],[Days Since Verified]])>VerifyDays),"Verify due","")) -> No location, Verify due | U20: Tab 8" row 18
A21: TAB8-017 | B21: Tablet 8" | C21: Tab 17 | F21: 350675292372179 | G21: MPL12621 | H21: MPL-CGO-OEQ-TBLT-00072 | I21: MPL12608 | J21: Dhiraagu 10GB | M21: Unverified | Q21: =IF(Register[[#This Row],[Last Verified]]="","",TODAY()-Register[[#This Row],[Last Verified]]) | R21: =_xlfn.TEXTJOIN(", ",TRUE,IF(Register[[#This Row],[Serial / IMEI]]="","No serial",""),IF(AND(Register[[#This Row],[Serial / IMEI]]<>"",COUNTIF(Register[Serial / IMEI],Register[[#This Row],[Serial / IMEI]])>1),"Duplicate serial",""),IF(AND(Register[[#This Row],[Asset Type]]<>"VHF",COUNTIFS(Register[Device Name / Code],Register[[#This Row],[Device Name / Code]],Register[Asset Type],Register[[#This Row],[Asset Type]])>1),"Duplicate name",""),IF(Register[[#This Row],[Location]]="","No location",""),IF(OR(Register[[#This Row],[Last Verified]]="",N(Register[[#This Row],[Days Since Verified]])>VerifyDays),"Verify due","")) -> No location, Verify due | U21: Tab 8" row 19
A22: TAB8-018 | B22: Tablet 8" | C22: Tab 18 | F22: 350675292375511 | G22: MPL12616 | H22: MPL-CGO-OEQ-TBLT-00067 | I22: MPL12609 | J22: Dhiraagu 10GB | M22: Unverified | Q22: =IF(Register[[#This Row],[Last Verified]]="","",TODAY()-Register[[#This Row],[Last Verified]]) | R22: =_xlfn.TEXTJOIN(", ",TRUE,IF(Register[[#This Row],[Serial / IMEI]]="","No serial",""),IF(AND(Register[[#This Row],[Serial / IMEI]]<>"",COUNTIF(Register[Serial / IMEI],Register[[#This Row],[Serial / IMEI]])>1),"Duplicate serial",""),IF(AND(Register[[#This Row],[Asset Type]]<>"VHF",COUNTIFS(Register[Device Name / Code],Register[[#This Row],[Device Name / Code]],Register[Asset Type],Register[[#This Row],[Asset Type]])>1),"Duplicate name",""),IF(Register[[#This Row],[Location]]="","No location",""),IF(OR(Register[[#This Row],[Last Verified]]="",N(Register[[#This Row],[Days Since Verified]])>VerifyDays),"Verify due","")) -> No location, Verify due | U22: Tab 8" row 20
A23: TAB8-019 | B23: Tablet 8" | C23: Tab 19 | F23: 350675292374688 | G23: MPL12619 | H23: MPL-CGO-OEQ-TBLT-00070 | I23: MPL12610 | J23: Dhiraagu 10GB | M23: Unverified | Q23: =IF(Register[[#This Row],[Last Verified]]="","",TODAY()-Register[[#This Row],[Last Verified]]) | R23: =_xlfn.TEXTJOIN(", ",TRUE,IF(Register[[#This Row],[Serial / IMEI]]="","No serial",""),IF(AND(Register[[#This Row],[Serial / IMEI]]<>"",COUNTIF(Register[Serial / IMEI],Register[[#This Row],[Serial / IMEI]])>1),"Duplicate serial",""),IF(AND(Register[[#This Row],[Asset Type]]<>"VHF",COUNTIFS(Register[Device Name / Code],Register[[#This Row],[Device Name / Code]],Register[Asset Type],Register[[#This Row],[Asset Type]])>1),"Duplicate name",""),IF(Register[[#This Row],[Location]]="","No location",""),IF(OR(Register[[#This Row],[Last Verified]]="",N(Register[[#This Row],[Days Since Verified]])>VerifyDays),"Verify due","")) -> No location, Verify due | U23: Tab 8" row 21
A24: TAB8-020 | B24: Tablet 8" | C24: Tab 20 | F24: 350675292367104 | G24: MPL12628 | H24: MPL-CGO-OEQ-TBLT-00079 | I24: MPL12611 | J24: Dhiraagu 10GB | K24: COD | L24: C Tallies | M24: In Use | O24: 44592 | Q24: =IF(Register[[#This Row],[Last Verified]]="","",TODAY()-Register[[#This Row],[Last Verified]]) | R24: =_xlfn.TEXTJOIN(", ",TRUE,IF(Register[[#This Row],[Serial / IMEI]]="","No serial",""),IF(AND(Register[[#This Row],[Serial / IMEI]]<>"",COUNTIF(Register[Serial / IMEI],Register[[#This Row],[Serial / IMEI]])>1),"Duplicate serial",""),IF(AND(Register[[#This Row],[Asset Type]]<>"VHF",COUNTIFS(Register[Device Name / Code],Register[[#This Row],[Device Name / Code]],Register[Asset Type],Register[[#This Row],[Asset Type]])>1),"Duplicate name",""),IF(Register[[#This Row],[Location]]="","No location",""),IF(OR(Register[[#This Row],[Last Verified]]="",N(Register[[#This Row],[Days Since Verified]])>VerifyDays),"Verify due","")) -> Verify due | S24: Battery Replaced 11.12.2024 | T24: At COD / Currently in use | U24: Tab 8" row 22
A25: TAB8-021 | B25: Tablet 8" | C25: Tab 21 | F25: 350675292372864 | G25: MPL12627 | H25: MPL-CGO-OEQ-TBLT-00078 | I25: MPL12612 | J25: Dhiraagu 10GB | K25: COD | L25: B Tallies | M25: In Use | Q25: =IF(Register[[#This Row],[Last Verified]]="","",TODAY()-Register[[#This Row],[Last Verified]]) | R25: =_xlfn.TEXTJOIN(", ",TRUE,IF(Register[[#This Row],[Serial / IMEI]]="","No serial",""),IF(AND(Register[[#This Row],[Serial / IMEI]]<>"",COUNTIF(Register[Serial / IMEI],Register[[#This Row],[Serial / IMEI]])>1),"Duplicate serial",""),IF(AND(Register[[#This Row],[Asset Type]]<>"VHF",COUNTIFS(Register[Device Name / Code],Register[[#This Row],[Device Name / Code]],Register[Asset Type],Register[[#This Row],[Asset Type]])>1),"Duplicate name",""),IF(Register[[#This Row],[Location]]="","No location",""),IF(OR(Register[[#This Row],[Last Verified]]="",N(Register[[#This Row],[Days Since Verified]])>VerifyDays),"Verify due","")) -> Verify due | T25: At COD / Currently in use | U25: Tab 8" row 23
A26: TAB8-022 | B26: Tablet 8" | C26: Tab 22 | F26: 350675292371312 | G26: MPL12629 | H26: MPL-CGO-OEQ-TBLT-00080 | I26: MPL12613 | J26: Dhiraagu 10GB | K26: COD | L26: C Tallies | M26: In Use | O26: 44592 | Q26: =IF(Register[[#This Row],[Last Verified]]="","",TODAY()-Register[[#This Row],[Last Verified]]) | R26: =_xlfn.TEXTJOIN(", ",TRUE,IF(Register[[#This Row],[Serial / IMEI]]="","No serial",""),IF(AND(Register[[#This Row],[Serial / IMEI]]<>"",COUNTIF(Register[Serial / IMEI],Register[[#This Row],[Serial / IMEI]])>1),"Duplicate serial",""),IF(AND(Register[[#This Row],[Asset Type]]<>"VHF",COUNTIFS(Register[Device Name / Code],Register[[#This Row],[Device Name / Code]],Register[Asset Type],Register[[#This Row],[Asset Type]])>1),"Duplicate name",""),IF(Register[[#This Row],[Location]]="","No location",""),IF(OR(Register[[#This Row],[Last Verified]]="",N(Register[[#This Row],[Days Since Verified]])>VerifyDays),"Verify due","")) -> Verify due | S26: Battery Replaced 11.12.2024 | T26: At COD / Currently in use | U26: Tab 8" row 24
A27: TAB8-023 | B27: Tablet 8" | C27: Tab 23 | F27: 350675292370603 | G27: MPL12612 | H27: MPL-CGO-OEQ-TBLT-00063 | I27: MPL12614 | J27: Dhiraagu 10GB | K27: COD | L27: A Tallies | M27: In Use | Q27: =IF(Register[[#This Row],[Last Verified]]="","",TODAY()-Register[[#This Row],[Last Verified]]) | R27: =_xlfn.TEXTJOIN(", ",TRUE,IF(Register[[#This Row],[Serial / IMEI]]="","No serial",""),IF(AND(Register[[#This Row],[Serial / IMEI]]<>"",COUNTIF(Register[Serial / IMEI],Register[[#This Row],[Serial / IMEI]])>1),"Duplicate serial",""),IF(AND(Register[[#This Row],[Asset Type]]<>"VHF",COUNTIFS(Register[Device Name / Code],Register[[#This Row],[Device Name / Code]],Register[Asset Type],Register[[#This Row],[Asset Type]])>1),"Duplicate name",""),IF(Register[[#This Row],[Location]]="","No location",""),IF(OR(Register[[#This Row],[Last Verified]]="",N(Register[[#This Row],[Days Since Verified]])>VerifyDays),"Verify due","")) -> Verify due | S27: Battery Replaced 11.12.2024 | T27: At COD / Currently in use | U27: Tab 8" row 25
A28: TAB8-024 | B28: Tablet 8" | C28: Tab 24 | F28: 350675292372005 | G28: MPL12611 | H28: MPL-CGO-OEQ-TBLT-00062 | I28: MPL12615 | J28: Dhiraagu 10GB | K28: HMT | L28: HMT | M28: In Use | N28: 45729 | Q28: =IF(Register[[#This Row],[Last Verified]]="","",TODAY()-Register[[#This Row],[Last Verified]]) | R28: =_xlfn.TEXTJOIN(", ",TRUE,IF(Register[[#This Row],[Serial / IMEI]]="","No serial",""),IF(AND(Register[[#This Row],[Serial / IMEI]]<>"",COUNTIF(Register[Serial / IMEI],Register[[#This Row],[Serial / IMEI]])>1),"Duplicate serial",""),IF(AND(Register[[#This Row],[Asset Type]]<>"VHF",COUNTIFS(Register[Device Name / Code],Register[[#This Row],[Device Name / Code]],Register[Asset Type],Register[[#This Row],[Asset Type]])>1),"Duplicate name",""),IF(Register[[#This Row],[Location]]="","No location",""),IF(OR(Register[[#This Row],[Last Verified]]="",N(Register[[#This Row],[Days Since Verified]])>VerifyDays),"Verify due","")) -> Verify due | T28: HMT 13.03.2025 | U28: Tab 8" row 26
A29: TAB8-025 | B29: Tablet 8" | C29: Tab 25 | F29: 350675292361289 | G29: MPL12631 | H29: MPL-CGO-OEQ-TBLT-00082 | I29: MPL12616 | J29: Dhiraagu 10GB | K29: COD | L29: A Tallies | M29: In Use | Q29: =IF(Register[[#This Row],[Last Verified]]="","",TODAY()-Register[[#This Row],[Last Verified]]) | R29: =_xlfn.TEXTJOIN(", ",TRUE,IF(Register[[#This Row],[Serial / IMEI]]="","No serial",""),IF(AND(Register[[#This Row],[Serial / IMEI]]<>"",COUNTIF(Register[Serial / IMEI],Register[[#This Row],[Serial / IMEI]])>1),"Duplicate serial",""),IF(AND(Register[[#This Row],[Asset Type]]<>"VHF",COUNTIFS(Register[Device Name / Code],Register[[#This Row],[Device Name / Code]],Register[Asset Type],Register[[#This Row],[Asset Type]])>1),"Duplicate name",""),IF(Register[[#This Row],[Location]]="","No location",""),IF(OR(Register[[#This Row],[Last Verified]]="",N(Register[[#This Row],[Days Since Verified]])>VerifyDays),"Verify due","")) -> Verify due | S29: Battery Replaced 11.12.2024 | T29: At COD / Currently in use, | U29: Tab 8" row 27
A30: TAB8-026 | B30: Tablet 8" | C30: Tab 26 | F30: 350675292378515 | G30: MPL12614 | H30: MPL-CGO-OEQ-TBLT-00065 | I30: MPL12617 | J30: Dhiraagu 10GB | K30: COD | L30: B Tallies | M30: In Use | Q30: =IF(Register[[#This Row],[Last Verified]]="","",TODAY()-Register[[#This Row],[Last Verified]]) | R30: =_xlfn.TEXTJOIN(", ",TRUE,IF(Register[[#This Row],[Serial / IMEI]]="","No serial",""),IF(AND(Register[[#This Row],[Serial / IMEI]]<>"",COUNTIF(Register[Serial / IMEI],Register[[#This Row],[Serial / IMEI]])>1),"Duplicate serial",""),IF(AND(Register[[#This Row],[Asset Type]]<>"VHF",COUNTIFS(Register[Device Name / Code],Register[[#This Row],[Device Name / Code]],Register[Asset Type],Register[[#This Row],[Asset Type]])>1),"Duplicate name",""),IF(Register[[#This Row],[Location]]="","No location",""),IF(OR(Register[[#This Row],[Last Verified]]="",N(Register[[#This Row],[Days Since Verified]])>VerifyDays),"Verify due","")) -> Verify due | T30: At COD / Currently in use | U30: Tab 8" row 28
A31: TAB8-027 | B31: Tablet 8" | C31: Tab 27 | F31: 350675292377301 | G31: MPL12622 | H31: MPL-CGO-OEQ-TBLT-00073 | I31: MPL12618 | J31: Dhiraagu 10GB | M31: Unverified | Q31: =IF(Register[[#This Row],[Last Verified]]="","",TODAY()-Register[[#This Row],[Last Verified]]) | R31: =_xlfn.TEXTJOIN(", ",TRUE,IF(Register[[#This Row],[Serial / IMEI]]="","No serial",""),IF(AND(Register[[#This Row],[Serial / IMEI]]<>"",COUNTIF(Register[Serial / IMEI],Register[[#This Row],[Serial / IMEI]])>1),"Duplicate serial",""),IF(AND(Register[[#This Row],[Asset Type]]<>"VHF",COUNTIFS(Register[Device Name / Code],Register[[#This Row],[Device Name / Code]],Register[Asset Type],Register[[#This Row],[Asset Type]])>1),"Duplicate name",""),IF(Register[[#This Row],[Location]]="","No location",""),IF(OR(Register[[#This Row],[Last Verified]]="",N(Register[[#This Row],[Days Since Verified]])>VerifyDays),"Verify due","")) -> No location, Verify due | U31: Tab 8" row 29
A32: TAB8-028 | B32: Tablet 8" | C32: Tab 28 | F32: 350675292373656 | G32: MPL12623 | H32: MPL-CGO-OEQ-TBLT-00074 | I32: MPL12619 | J32: Dhiraagu 10GB | M32: Unverified | Q32: =IF(Register[[#This Row],[Last Verified]]="","",TODAY()-Register[[#This Row],[Last Verified]]) | R32: =_xlfn.TEXTJOIN(", ",TRUE,IF(Register[[#This Row],[Serial / IMEI]]="","No serial",""),IF(AND(Register[[#This Row],[Serial / IMEI]]<>"",COUNTIF(Register[Serial / IMEI],Register[[#This Row],[Serial / IMEI]])>1),"Duplicate serial",""),IF(AND(Register[[#This Row],[Asset Type]]<>"VHF",COUNTIFS(Register[Device Name / Code],Register[[#This Row],[Device Name / Code]],Register[Asset Type],Register[[#This Row],[Asset Type]])>1),"Duplicate name",""),IF(Register[[#This Row],[Location]]="","No location",""),IF(OR(Register[[#This Row],[Last Verified]]="",N(Register[[#This Row],[Days Since Verified]])>VerifyDays),"Verify due","")) -> No location, Verify due | U32: Tab 8" row 30
A33: TAB8-029 | B33: Tablet 8" | C33: Tab 29 | F33: 350675292369043 | G33: MPL12615 | H33: MPL-CGO-OEQ-TBLT-00066 | I33: MPL12620 | J33: Dhiraagu 10GB | M33: Unverified | Q33: =IF(Register[[#This Row],[Last Verified]]="","",TODAY()-Register[[#This Row],[Last Verified]]) | R33: =_xlfn.TEXTJOIN(", ",TRUE,IF(Register[[#This Row],[Serial / IMEI]]="","No serial",""),IF(AND(Register[[#This Row],[Serial / IMEI]]<>"",COUNTIF(Register[Serial / IMEI],Register[[#This Row],[Serial / IMEI]])>1),"Duplicate serial",""),IF(AND(Register[[#This Row],[Asset Type]]<>"VHF",COUNTIFS(Register[Device Name / Code],Register[[#This Row],[Device Name / Code]],Register[Asset Type],Register[[#This Row],[Asset Type]])>1),"Duplicate name",""),IF(Register[[#This Row],[Location]]="","No location",""),IF(OR(Register[[#This Row],[Last Verified]]="",N(Register[[#This Row],[Days Since Verified]])>VerifyDays),"Verify due","")) -> No location, Verify due | U33: Tab 8" row 31
A34: TAB8-030 | B34: Tablet 8" | C34: Tab 30 | F34: 350675292372658 | G34: MPL12618 | H34: MPL-CGO-OEQ-TBLT-00069 | I34: MPL12621 | J34: Dhiraagu 10GB / 1589 7592 | K34: Container Yard | L34: C Yard | M34: In Use | N34: 44829 | Q34: =IF(Register[[#This Row],[Last Verified]]="","",TODAY()-Register[[#This Row],[Last Verified]]) | R34: =_xlfn.TEXTJOIN(", ",TRUE,IF(Register[[#This Row],[Serial / IMEI]]="","No serial",""),IF(AND(Register[[#This Row],[Serial / IMEI]]<>"",COUNTIF(Register[Serial / IMEI],Register[[#This Row],[Serial / IMEI]])>1),"Duplicate serial",""),IF(AND(Register[[#This Row],[Asset Type]]<>"VHF",COUNTIFS(Register[Device Name / Code],Register[[#This Row],[Device Name / Code]],Register[Asset Type],Register[[#This Row],[Asset Type]])>1),"Duplicate name",""),IF(Register[[#This Row],[Location]]="","No location",""),IF(OR(Register[[#This Row],[Last Verified]]="",N(Register[[#This Row],[Days Since Verified]])>VerifyDays),"Verify due","")) -> Verify due | T34: Container Yard (25.09.2022) | U34: Tab 8" row 32
A35: TAB8-031 | B35: Tablet 8" | C35: Tab 31 | F35: 350675292374803 | G35: MPL12624 | H35: MPL-CGO-OEQ-TBLT-00075 | I35: MPL12622 | J35: Ooredoo 10GB | K35: HMT | M35: In Use | N35: 44539 | Q35: =IF(Register[[#This Row],[Last Verified]]="","",TODAY()-Register[[#This Row],[Last Verified]]) | R35: =_xlfn.TEXTJOIN(", ",TRUE,IF(Register[[#This Row],[Serial / IMEI]]="","No serial",""),IF(AND(Register[[#This Row],[Serial / IMEI]]<>"",COUNTIF(Register[Serial / IMEI],Register[[#This Row],[Serial / IMEI]])>1),"Duplicate serial",""),IF(AND(Register[[#This Row],[Asset Type]]<>"VHF",COUNTIFS(Register[Device Name / Code],Register[[#This Row],[Device Name / Code]],Register[Asset Type],Register[[#This Row],[Asset Type]])>1),"Duplicate name",""),IF(Register[[#This Row],[Location]]="","No location",""),IF(OR(Register[[#This Row],[Last Verified]]="",N(Register[[#This Row],[Days Since Verified]])>VerifyDays),"Verify due","")) -> Verify due | T35: Use in HMT(sent on 09.12.2021) | U35: Tab 8" row 33
A36: TAB8-032 | B36: Tablet 8" | C36: Tab 32 | F36: 350675292376444 | G36: MPL12626 | H36: MPL-CGO-OEQ-TBLT-00077 | I36: MPL12623 | J36: Ooredoo 10GB | K36: HMT | M36: In Use | N36: 44539 | Q36: =IF(Register[[#This Row],[Last Verified]]="","",TODAY()-Register[[#This Row],[Last Verified]]) | R36: =_xlfn.TEXTJOIN(", ",TRUE,IF(Register[[#This Row],[Serial / IMEI]]="","No serial",""),IF(AND(Register[[#This Row],[Serial / IMEI]]<>"",COUNTIF(Register[Serial / IMEI],Register[[#This Row],[Serial / IMEI]])>1),"Duplicate serial",""),IF(AND(Register[[#This Row],[Asset Type]]<>"VHF",COUNTIFS(Register[Device Name / Code],Register[[#This Row],[Device Name / Code]],Register[Asset Type],Register[[#This Row],[Asset Type]])>1),"Duplicate name",""),IF(Register[[#This Row],[Location]]="","No location",""),IF(OR(Register[[#This Row],[Last Verified]]="",N(Register[[#This Row],[Days Since Verified]])>VerifyDays),"Verify due","")) -> Verify due | T36: Use in HMT(sent on 09.12.2021) | U36: Tab 8" row 34
A37: TAB8-033 | B37: Tablet 8" | C37: Tab 33 | F37: 350675292384000 | G37: MPL12610 | H37: MPL-CGO-OEQ-TBLT-00061 | I37: MPL12625 | J37: Ooredoo 10GB | K37: Marine Craft | L37: Raazy | M37: In Use | Q37: =IF(Register[[#This Row],[Last Verified]]="","",TODAY()-Register[[#This Row],[Last Verified]]) | R37: =_xlfn.TEXTJOIN(", ",TRUE,IF(Register[[#This Row],[Serial / IMEI]]="","No serial",""),IF(AND(Register[[#This Row],[Serial / IMEI]]<>"",COUNTIF(Register[Serial / IMEI],Register[[#This Row],[Serial / IMEI]])>1),"Duplicate serial",""),IF(AND(Register[[#This Row],[Asset Type]]<>"VHF",COUNTIFS(Register[Device Name / Code],Register[[#This Row],[Device Name / Code]],Register[Asset Type],Register[[#This Row],[Asset Type]])>1),"Duplicate name",""),IF(Register[[#This Row],[Location]]="","No location",""),IF(OR(Register[[#This Row],[Last Verified]]="",N(Register[[#This Row],[Days Since Verified]])>VerifyDays),"Verify due","")) -> Verify due | T37: Marine Craft - Raazy | U37: Tab 8" row 35
A38: TAB8-034 | B38: Tablet 8" | C38: Tab 34 | F38: 350675292367732 | G38: MPL12620 | H38: MPL-CGO-OEQ-TBLT-00071 | I38: MPL12627 | J38: Ooredoo 10GB | K38: Marine Craft | L38: Raazy | M38: In Use | Q38: =IF(Register[[#This Row],[Last Verified]]="","",TODAY()-Register[[#This Row],[Last Verified]]) | R38: =_xlfn.TEXTJOIN(", ",TRUE,IF(Register[[#This Row],[Serial / IMEI]]="","No serial",""),IF(AND(Register[[#This Row],[Serial / IMEI]]<>"",COUNTIF(Register[Serial / IMEI],Register[[#This Row],[Serial / IMEI]])>1),"Duplicate serial",""),IF(AND(Register[[#This Row],[Asset Type]]<>"VHF",COUNTIFS(Register[Device Name / Code],Register[[#This Row],[Device Name / Code]],Register[Asset Type],Register[[#This Row],[Asset Type]])>1),"Duplicate name",""),IF(Register[[#This Row],[Location]]="","No location",""),IF(OR(Register[[#This Row],[Last Verified]]="",N(Register[[#This Row],[Days Since Verified]])>VerifyDays),"Verify due","")) -> Verify due | T38: Marine Craft - Raazy | U38: Tab 8" row 36
A39: TAB8-035 | B39: Tablet 8" | C39: Tab 35 | F39: 350675292373540 | G39: MPL12617 | H39: MPL-CGO-OEQ-TBLT-00068 | I39: MPL12628 | J39: Ooredoo 10GB | K39: Marine Craft | L39: Raazy | M39: In Use | Q39: =IF(Register[[#This Row],[Last Verified]]="","",TODAY()-Register[[#This Row],[Last Verified]]) | R39: =_xlfn.TEXTJOIN(", ",TRUE,IF(Register[[#This Row],[Serial / IMEI]]="","No serial",""),IF(AND(Register[[#This Row],[Serial / IMEI]]<>"",COUNTIF(Register[Serial / IMEI],Register[[#This Row],[Serial / IMEI]])>1),"Duplicate serial",""),IF(AND(Register[[#This Row],[Asset Type]]<>"VHF",COUNTIFS(Register[Device Name / Code],Register[[#This Row],[Device Name / Code]],Register[Asset Type],Register[[#This Row],[Asset Type]])>1),"Duplicate name",""),IF(Register[[#This Row],[Location]]="","No location",""),IF(OR(Register[[#This Row],[Last Verified]]="",N(Register[[#This Row],[Days Since Verified]])>VerifyDays),"Verify due","")) -> Verify due | T39: Marine Craft - Raazy | U39: Tab 8" row 37
A40: TAB8-036 | B40: Tablet 8" | C40: Tab 36 | F40: 350675292367625 | G40: MPL12633 | H40: MPL-CGO-OEQ-TBLT-00084 | I40: MPL12629 | J40: Ooredoo 10GB | K40: Marine Craft | L40: Raazy | M40: In Use | Q40: =IF(Register[[#This Row],[Last Verified]]="","",TODAY()-Register[[#This Row],[Last Verified]]) | R40: =_xlfn.TEXTJOIN(", ",TRUE,IF(Register[[#This Row],[Serial / IMEI]]="","No serial",""),IF(AND(Register[[#This Row],[Serial / IMEI]]<>"",COUNTIF(Register[Serial / IMEI],Register[[#This Row],[Serial / IMEI]])>1),"Duplicate serial",""),IF(AND(Register[[#This Row],[Asset Type]]<>"VHF",COUNTIFS(Register[Device Name / Code],Register[[#This Row],[Device Name / Code]],Register[Asset Type],Register[[#This Row],[Asset Type]])>1),"Duplicate name",""),IF(Register[[#This Row],[Location]]="","No location",""),IF(OR(Register[[#This Row],[Last Verified]]="",N(Register[[#This Row],[Days Since Verified]])>VerifyDays),"Verify due","")) -> Verify due | T40: Marine Craft - Raazy | U40: Tab 8" row 38
A41: TAB8-037 | B41: Tablet 8" | C41: Tab 37 | F41: 350675292372369 | G41: MPL12630 | H41: MPL-CGO-OEQ-TBLT-00081 | I41: MPL12630 | J41: Ooredoo 10GB | K41: Marine Craft | L41: Raazy | M41: In Use | Q41: =IF(Register[[#This Row],[Last Verified]]="","",TODAY()-Register[[#This Row],[Last Verified]]) | R41: =_xlfn.TEXTJOIN(", ",TRUE,IF(Register[[#This Row],[Serial / IMEI]]="","No serial",""),IF(AND(Register[[#This Row],[Serial / IMEI]]<>"",COUNTIF(Register[Serial / IMEI],Register[[#This Row],[Serial / IMEI]])>1),"Duplicate serial",""),IF(AND(Register[[#This Row],[Asset Type]]<>"VHF",COUNTIFS(Register[Device Name / Code],Register[[#This Row],[Device Name / Code]],Register[Asset Type],Register[[#This Row],[Asset Type]])>1),"Duplicate name",""),IF(Register[[#This Row],[Location]]="","No location",""),IF(OR(Register[[#This Row],[Last Verified]]="",N(Register[[#This Row],[Days Since Verified]])>VerifyDays),"Verify due","")) -> Verify due | T41: Marine Craft - Raazy | U41: Tab 8" row 39
...

Sheet Movement Log
A1: Movement & Repair Log
A2: Add one row per event (issue, return, transfer, repair, verification). Pick the Asset ID — device name and type fill in automatically. Then update Location/Status on the Asset Register.
A4: Date | B4: Asset ID | C4: Device Name | D4: Asset Type | E4: Action | F4: From | G4: To | H4: Assigned To | I4: Done By | J4: Notes | K4: Register Location Now
C5: =IF(MoveLog[[#This Row],[Asset ID]]="","",_xlfn.XLOOKUP(MoveLog[[#This Row],[Asset ID]],Register[Asset ID],Register[Device Name / Code],"Not found")) | D5: =IF(MoveLog[[#This Row],[Asset ID]]="","",_xlfn.XLOOKUP(MoveLog[[#This Row],[Asset ID]],Register[Asset ID],Register[Asset Type],"Not found")) | E5: Issue | K5: =IF(MoveLog[[#This Row],[Asset ID]]="","",_xlfn.XLOOKUP(MoveLog[[#This Row],[Asset ID]],Register[Asset ID],Register[Location],"")&"")

Sheet Lists
A1: Asset Type | B1: Status | C1: Location | D1: Log Action | E1: SIM Operator | F1: Settings
A2: Tablet 8" | B2: In Use | C2: COD | D2: Issue | E2: Dhiraagu 10GB | F2: Verify every (days) | G2: 90
A3: Tablet 10" | B3: In Stock | C3: Container Yard | D3: Return | E3: Dhiraagu 20GB | F3: Asset ID prefixes → | G3: TAB8 / TAB10 / PC / VHF / VHFU
A4: PC | B4: Under Repair | C4: Thilafushi | D4: Transfer | E4: Ooredoo 10GB
A5: VHF | B5: Damaged | C5: HMT | D5: Repair Out | E5: None
B6: Unverified | C6: Marine Craft | D6: Repair In
B7: Not in Use | C7: Yard Office | D7: Mark Damaged
B8: Disposed | C8: IT | D8: Verified
B9: Lost | C9: POD-MCH | D9: Dispose
C10: POD-HMT | D10: OS Update
C11: POD Office
C12: Gear Store
C13: Cargo Office
C14: MCD
C15: Office
C16: MCH
A17: Add new values at the bottom of each list — dropdowns pick them up automatically (blank rows are ignored).

Sheet Tab 8"
A2: TAB No. | B2: Opt | C2: IMEI | D2: Inventory Number | E2: Asset number | F2: Sim Number | G2: Shift | H2: Last OS update | I2: Remarks | J2: Repair
A3: Tab 1 | B3: Dhiraagu 10GB | C3: 350675291199268 | E3: MPL-CGO-OEQ-TBLT-00039 | G3: B Tallies | I3: At COD / Currently in use | K3: MPL14916
A4: Tab 2 | B4: Dhiraagu 10GB | C4: 350675291330186 | E4: MPL-CGO-OEQ-TBLT-00040 | G4: C Yard | I4: Container Yard (25.09.2022) | K4: MPL14915
A5: Tab 3 | B5: Dhiraagu 10GB | C5: 350675291332695 | E5: MPL-CGO-OEQ-TBLT-00041 | G5: C Tallies | H5: 31.1.2022 | I5: At COD / Currently in use | J5: Battery Replaced 11.12.2024 | K5: MPL14914
A6: Tab 4 | B6: Dhiraagu 10GB | C6: 350675291222482 | E6: MPL-CGO-OEQ-TBLT-00042 | G6: C Yard | I6: Container Yard (01.06.2021) | K6: MPL14913
A7: Tab 5 | B7: Dhiraagu 10GB | C7: 350675291334022 | E7: MPL-CGO-OEQ-TBLT-00043 | I7: Security for Thilafushi Ops | K7: MPL14912
A8: Tab 6 | B8: Dhiraagu 10GB | C8: 350675291228877 | E8: MPL-CGO-OEQ-TBLT-00044 | I8: Use in HMT(sent on 23.05.2021) | K8: MPL14911
A9: Tab 7 | B9: Dhiraagu 10GB | C9: 350675291228992 | E9: MPL-CGO-OEQ-TBLT-00045 | I9: Use in HMT(sent on 23.05.2021) | K9: MPL14910
A10: Tab 8 | B10: Dhiraagu 10GB | C10: 350675291331135 | E10: MPL-CGO-OEQ-TBLT-00046 | G10: A Tallies | I10: At COD / Currently in use | K10: MPL14909
A11: Tab 9 | B11: Dhiraagu 10GB | C11: 350675291329451 | E11: MPL-CGO-OEQ-TBLT-00047 | G11: A Tallies | I11: At COD / Currently in use | K11: MPL14908
A12: Tab 10 | B12: Dhiraagu 10GB | C12: 350675291331085 | E12: MPL-CGO-OEQ-TBLT-00048 | I12: Yard Office (21.04.2021) | K12: MPL14907
A13: Tab 11 | B13: Dhiraagu 10GB | C13: 350675291228844 | E13: MPL-CGO-OEQ-TBLT-00051 | G13: B Tallies | I13: At COD / Currently in use | K13: MPL14906
A14: Tab 12 | B14: Dhiraagu 10GB | C14: 350675291332265 | E14: MPL-CGO-OEQ-TBLT-00052 | I14: At IT (Tab back light issue) - Given to IT for Repair | K14: MPL14905
A15: Tab 13 | B15: Dhiraagu 10GB | C15: 350675291222417 | E15: MPL-CGO-OEQ-TBLT-00053 | G15: HMT (13.03.2025) | H15: 31.1.2022 | I15: At COD / Currently in use, HMT 13.03.2025 | K15: MPL14904
A16: Tab 14 | B16: Dhiraagu 10GB | C16: 350675291222318 | E16: MPL-CGO-OEQ-TBLT-00050 | I16: At IT (Tab back light issue) - Given to IT for Repair | K16: MPL14903
A17: Tab 15 | B17: Dhiraagu 10GB | C17: 350675291222557 | E17: MPL-CGO-OEQ-TBLT-00049 | G17: B Tallies | I17: At COD / Currently in use | K17: MPL14902
A18: Tab 16 | B18: Dhiraagu 10GB | C18: 350675292375321 | D18: MPL12613 | E18: MPL-CGO-OEQ-TBLT-00064 | K18: MPL12607
A19: Tab 17 | B19: Dhiraagu 10GB | C19: 350675292372179 | D19: MPL12621 | E19: MPL-CGO-OEQ-TBLT-00072 | K19: MPL12608
A20: Tab 18 | B20: Dhiraagu 10GB | C20: 350675292375511 | D20: MPL12616 | E20: MPL-CGO-OEQ-TBLT-00067 | K20: MPL12609
A21: Tab 19 | B21: Dhiraagu 10GB | C21: 350675292374688 | D21: MPL12619 | E21: MPL-CGO-OEQ-TBLT-00070 | K21: MPL12610
A22: Tab 20 | B22: Dhiraagu 10GB | C22: 350675292367104 | D22: MPL12628 | E22: MPL-CGO-OEQ-TBLT-00079 | G22: C Tallies | H22: 31.1.2022 | I22: At COD / Currently in use | J22: Battery Replaced 11.12.2024 | K22: MPL12611
A23: Tab 21 | B23: Dhiraagu 10GB | C23: 350675292372864 | D23: MPL12627 | E23: MPL-CGO-OEQ-TBLT-00078 | G23: B Tallies | I23: At COD / Currently in use | K23: MPL12612
A24: Tab 22 | B24: Dhiraagu 10GB | C24: 350675292371312 | D24: MPL12629 | E24: MPL-CGO-OEQ-TBLT-00080 | G24: C Tallies | H24: 31.1.2022 | I24: At COD / Currently in use | J24: Battery Replaced 11.12.2024 | K24: MPL12613
A25: Tab 23 | B25: Dhiraagu 10GB | C25: 350675292370603 | D25: MPL12612 | E25: MPL-CGO-OEQ-TBLT-00063 | G25: A Tallies | I25: At COD / Currently in use | J25: Battery Replaced 11.12.2024 | K25: MPL12614
A26: Tab 24 | B26: Dhiraagu 10GB | C26: 350675292372005 | D26: MPL12611 | E26: MPL-CGO-OEQ-TBLT-00062 | G26: HMT (13.03.2025) | I26: HMT 13.03.2025 | K26: MPL12615
A27: Tab 25 | B27: Dhiraagu 10GB | C27: 350675292361289 | D27: MPL12631 | E27: MPL-CGO-OEQ-TBLT-00082 | G27: A Tallies | I27: At COD / Currently in use, | J27: Battery Replaced 11.12.2024 | K27: MPL12616
A28: Tab 26 | B28: Dhiraagu 10GB | C28: 350675292378515 | D28: MPL12614 | E28: MPL-CGO-OEQ-TBLT-00065 | G28: B Tallies | I28: At COD / Currently in use | K28: MPL12617
A29: Tab 27 | B29: Dhiraagu 10GB | C29: 350675292377301 | D29: MPL12622 | E29: MPL-CGO-OEQ-TBLT-00073 | K29: MPL12618
A30: Tab 28 | B30: Dhiraagu 10GB | C30: 350675292373656 | D30: MPL12623 | E30: MPL-CGO-OEQ-TBLT-00074 | K30: MPL12619
A31: Tab 29 | B31: Dhiraagu 10GB | C31: 350675292369043 | D31: MPL12615 | E31: MPL-CGO-OEQ-TBLT-00066 | K31: MPL12620
A32: Tab 30 | B32: Dhiraagu 10GB | C32: 350675292372658 | D32: MPL12618 | E32: MPL-CGO-OEQ-TBLT-00069 | F32: 1589 7592 | G32: C Yard | I32: Container Yard (25.09.2022) | K32: MPL12621
A33: Tab 31 | B33: Ooredoo 10GB | C33: 350675292374803 | D33: MPL12624 | E33: MPL-CGO-OEQ-TBLT-00075 | I33: Use in HMT(sent on 09.12.2021) | K33: MPL12622
A34: Tab 32 | B34: Ooredoo 10GB | C34: 350675292376444 | D34: MPL12626 | E34: MPL-CGO-OEQ-TBLT-00077 | I34: Use in HMT(sent on 09.12.2021) | K34: MPL12623
A35: Tab 33 | B35: Ooredoo 10GB | C35: 350675292384000 | D35: MPL12610 | E35: MPL-CGO-OEQ-TBLT-00061 | I35: Marine Craft - Raazy | K35: MPL12625
A36: Tab 34 | B36: Ooredoo 10GB | C36: 350675292367732 | D36: MPL12620 | E36: MPL-CGO-OEQ-TBLT-00071 | I36: Marine Craft - Raazy | K36: MPL12627
A37: Tab 35 | B37: Ooredoo 10GB | C37: 350675292373540 | D37: MPL12617 | E37: MPL-CGO-OEQ-TBLT-00068 | I37: Marine Craft - Raazy | K37: MPL12628
A38: Tab 36 | B38: Ooredoo 10GB | C38: 350675292367625 | D38: MPL12633 | E38: MPL-CGO-OEQ-TBLT-00084 | I38: Marine Craft - Raazy | K38: MPL12629
A39: Tab 37 | B39: Ooredoo 10GB | C39: 350675292372369 | D39: MPL12630 | E39: MPL-CGO-OEQ-TBLT-00081 | I39: Marine Craft - Raazy | K39: MPL12630
A40: Tab 38 | B40: Ooredoo 10GB | C40: 350675292367831 | D40: MPL12625 | E40: MPL-CGO-OEQ-TBLT-00076 | G40: C Tallies | H40: 31.1.2022 | I40: At COD / Currently in use | J40: Battery Replaced 11.12.2024 | K40: MPL12631
A41: Tab 39 | B41: Ooredoo 10GB | C41: 350675292372237 | D41: MPL12632 | E41: MPL-CGO-OEQ-TBLT-00083 | G41: C Tallies | H41: 31.1.2022 | I41: At COD / Currently in use | J41: Battery Replaced 11.12.2024 | K41: MPL12632
...

Sheet Tab 10"
A2: # | B2: TAB No. | C2: Opt | D2: Sim No. | E2: IMEI | F2: Inventory Number | G2: Asset number | H2: Location | I2: Last OS update | J2: Remarks | K2: Repair
A3: 11 | B3: COD TAB032 | C3: Dhiraagu 10GB | D3: 1675 4957 | E3: 356904752482896 | F3: MPL21845 | H3: B
A4: 1 | B4: COD TAB033 | C4: Dhiraagu 20GB | E4: 356904752487127 | F4: MPL21833 | H4: C-Yard | J4: 11.02.2026
A5: 15 | B5: COD TAB034 | C5: Dhiraagu 10GB | D5: 1675 4958 | E5: 356904751788400 | F5: MPL21834 | H5: C
A6: 12 | B6: COD TAB035 | C6: Dhiraagu 10GB | D6: 1675 4955 | E6: 356904852486251 | F6: MPL21835 | H6: C
A7: 2 | B7: COD TAB036 | C7: Dhiraagu 20GB | E7: 356904752488133 | F7: MPL21836 | H7: C-Yard | J7: 14.03.2026
A8: 8 | B8: COD TAB037 | C8: Dhiraagu 10GB | D8: 1675 4956 | E8: 356904752488083 | F8: MPL21837 | H8: B
A9: 20 | B9: COD TAB038 | C9: Dhiraagu 10GB | D9: 1654 6458 | E9: 356904752488737 | F9: MPL21842 | H9: C - 07.07.2026 | J9: Received without Charger
A10: 9 | B10: COD TAB039 | C10: Dhiraagu 10GB | D10: 1675 4961 | E10: 356904752477680 | F10: MPL21839 | H10: C
A11: 3 | B11: COD TAB040 | C11: Dhiraagu 20GB | E11: 356904752478043 | F11: MPL21840 | H11: HMT - 31.05.25
A12: 7 | B12: COD TAB041 | C12: Dhiraagu 10GB | D12: 1675 4963 | E12: 356904752488901 | F12: MPL21841 | H12: A
A13: 19 | B13: COD TAB042 | C13: Dhiraagu 10GB | D13: 1654 6160 | H13: C - 07.07.2026 | J13: Received without Charger
A14: 16 | B14: COD TAB043 | C14: Dhiraagu 10GB | E14: 356904751791669 | F14: MPL21843 | H14: HMT - 31.05.25
A15: 14 | B15: COD TAB044 | C15: Dhiraagu 10GB | D15: 1675 4959 | E15: 356904752486376 | F15: MPL21844 | H15: B
A16: 4 | B16: COD TAB045 | C16: Dhiraagu 20GB | E16: 356904751810964 | F16: MPL21847 | H16: HMT - 31.05.25
A17: 5 | B17: COD TAB046 | C17: Dhiraagu 20GB | D17: 1603 4966 | E17: 356904752484454 | F17: MPL21846 | H17: C-Yard
A18: 6 | B18: COD TAB047 | C18: Dhiraagu 20GB | D18: 1603 4964 | E18: 356904751785794 | F18: MPL21852 | H18: C-Yard
A19: 17 | B19: COD TAB048 | C19: Dhiraagu 10GB | E19: 356904752482599 | F19: MPL21848 | H19: HMT - 31.05.25
A20: 18 | B20: COD TAB049 | C20: Dhiraagu 10GB | D20: 1675 4954 | E20: 356904752484165 | F20: MPL21849 | H20: C-Yard - Thilafushi | J20: 25.4.2026
A21: 13 | B21: COD TAB050 | C21: Dhiraagu 10GB | D21: 1675 4953 | E21: 356904752481096 | F21: MPL21850 | H21: A
A22: 10 | B22: COD TAB051 | C22: Dhiraagu 10GB | D22: 1675 4962 | E22: 356904750632443 | F22: MPL21851 | H22: A
E26: 3
E27: 7
E28: 7
E29: 7

Sheet PC
